Workbook

Sheet Summary
A1: Server hardening scripts vs the CIS PDFs Qualys uses
A2: Member-server recommendations only (domain-controller-only items excluded). Counts are live formulas.
A4: CIS benchmark | B4: Script | C4: Level | D4: Items | E4: Covered | F4: Check value | G4: Manual step | H4: Different / Missing | I4: Covered %
A5: Server 2022 v5.1.0 | B5: CIS_Server2022_Hardening.ps1 | C5: L1 | D5: =COUNTIF('Server 2022 v5.1.0'!$B:$B,C5) -> 299 | E5: =COUNTIFS('Server 2022 v5.1.0'!$B:$B,C5,'Server 2022 v5.1.0'!$G:$G,"Covered")+COUNTIFS('Server 2022 v5.1.0'!$B:$B,C5,'Server 2022 v5.1.0'!$G:$G,"Covered (reviewed)") -> 286 | F5: =COUNTIFS('Server 2022 v5.1.0'!$B:$B,C5,'Server 2022 v5.1.0'!$G:$G,"Covered - check value") -> 13 | G5: =COUNTIFS('Server 2022 v5.1.0'!$B:$B,C5,'Server 2022 v5.1.0'!$G:$G,"Manual step") -> 0 | H5: =COUNTIFS('Server 2022 v5.1.0'!$B:$B,C5,'Server 2022 v5.1.0'!$G:$G,"Different value")+COUNTIFS('Server 2022 v5.1.0'!$B:$B,C5,'Server 2022 v5.1.0'!$G:$G,"Missing") -> 0 | I5: =IFERROR((E5+F5)/D5,0) -> 1
A6: Server 2022 v5.1.0 | B6: CIS_Server2022_Hardening.ps1 | C6: L2 | D6: =COUNTIF('Server 2022 v5.1.0'!$B:$B,C6) -> 72 | E6: =COUNTIFS('Server 2022 v5.1.0'!$B:$B,C6,'Server 2022 v5.1.0'!$G:$G,"Covered")+COUNTIFS('Server 2022 v5.1.0'!$B:$B,C6,'Server 2022 v5.1.0'!$G:$G,"Covered (reviewed)") -> 71 | F6: =COUNTIFS('Server 2022 v5.1.0'!$B:$B,C6,'Server 2022 v5.1.0'!$G:$G,"Covered - check value") -> 1 | G6: =COUNTIFS('Server 2022 v5.1.0'!$B:$B,C6,'Server 2022 v5.1.0'!$G:$G,"Manual step") -> 0 | H6: =COUNTIFS('Server 2022 v5.1.0'!$B:$B,C6,'Server 2022 v5.1.0'!$G:$G,"Different value")+COUNTIFS('Server 2022 v5.1.0'!$B:$B,C6,'Server 2022 v5.1.0'!$G:$G,"Missing") -> 0 | I6: =IFERROR((E6+F6)/D6,0) -> 1
A7: Server 2019 v5.0.0 | B7: CIS_Server2019_Hardening.ps1 | C7: L1 | D7: =COUNTIF('Server 2019 v5.0.0'!$B:$B,C7) -> 297 | E7: =COUNTIFS('Server 2019 v5.0.0'!$B:$B,C7,'Server 2019 v5.0.0'!$G:$G,"Covered")+COUNTIFS('Server 2019 v5.0.0'!$B:$B,C7,'Server 2019 v5.0.0'!$G:$G,"Covered (reviewed)") -> 284 | F7: =COUNTIFS('Server 2019 v5.0.0'!$B:$B,C7,'Server 2019 v5.0.0'!$G:$G,"Covered - check value") -> 13 | G7: =COUNTIFS('Server 2019 v5.0.0'!$B:$B,C7,'Server 2019 v5.0.0'!$G:$G,"Manual step") -> 0 | H7: =COUNTIFS('Server 2019 v5.0.0'!$B:$B,C7,'Server 2019 v5.0.0'!$G:$G,"Different value")+COUNTIFS('Server 2019 v5.0.0'!$B:$B,C7,'Server 2019 v5.0.0'!$G:$G,"Missing") -> 0 | I7: =IFERROR((E7+F7)/D7,0) -> 1
A8: Server 2019 v5.0.0 | B8: CIS_Server2019_Hardening.ps1 | C8: L2 | D8: =COUNTIF('Server 2019 v5.0.0'!$B:$B,C8) -> 69 | E8: =COUNTIFS('Server 2019 v5.0.0'!$B:$B,C8,'Server 2019 v5.0.0'!$G:$G,"Covered")+COUNTIFS('Server 2019 v5.0.0'!$B:$B,C8,'Server 2019 v5.0.0'!$G:$G,"Covered (reviewed)") -> 68 | F8: =COUNTIFS('Server 2019 v5.0.0'!$B:$B,C8,'Server 2019 v5.0.0'!$G:$G,"Covered - check value") -> 1 | G8: =COUNTIFS('Server 2019 v5.0.0'!$B:$B,C8,'Server 2019 v5.0.0'!$G:$G,"Manual step") -> 0 | H8: =COUNTIFS('Server 2019 v5.0.0'!$B:$B,C8,'Server 2019 v5.0.0'!$G:$G,"Different value")+COUNTIFS('Server 2019 v5.0.0'!$B:$B,C8,'Server 2019 v5.0.0'!$G:$G,"Missing") -> 0 | I8: =IFERROR((E8+F8)/D8,0) -> 1
A9: Server 2016 v4.0.0 | B9: CIS_Server2016_Hardening.ps1 | C9: L1 | D9: =COUNTIF('Server 2016 v4.0.0'!$B:$B,C9) -> 321 | E9: =COUNTIFS('Server 2016 v4.0.0'!$B:$B,C9,'Server 2016 v4.0.0'!$G:$G,"Covered")+COUNTIFS('Server 2016 v4.0.0'!$B:$B,C9,'Server 2016 v4.0.0'!$G:$G,"Covered (reviewed)") -> 307 | F9: =COUNTIFS('Server 2016 v4.0.0'!$B:$B,C9,'Server 2016 v4.0.0'!$G:$G,"Covered - check value") -> 13 | G9: =COUNTIFS('Server 2016 v4.0.0'!$B:$B,C9,'Server 2016 v4.0.0'!$G:$G,"Manual step") -> 1 | H9: =COUNTIFS('Server 2016 v4.0.0'!$B:$B,C9,'Server 2016 v4.0.0'!$G:$G,"Different value")+COUNTIFS('Server 2016 v4.0.0'!$B:$B,C9,'Server 2016 v4.0.0'!$G:$G,"Missing") -> 0 | I9: =IFERROR((E9+F9)/D9,0) -> 0.99688474
A10: Server 2016 v4.0.0 | B10: CIS_Server2016_Hardening.ps1 | C10: L2 | D10: =COUNTIF('Server 2016 v4.0.0'!$B:$B,C10) -> 67 | E10: =COUNTIFS('Server 2016 v4.0.0'!$B:$B,C10,'Server 2016 v4.0.0'!$G:$G,"Covered")+COUNTIFS('Server 2016 v4.0.0'!$B:$B,C10,'Server 2016 v4.0.0'!$G:$G,"Covered (reviewed)") -> 65 | F10: =COUNTIFS('Server 2016 v4.0.0'!$B:$B,C10,'Server 2016 v4.0.0'!$G:$G,"Covered - check value") -> 2 | G10: =COUNTIFS('Server 2016 v4.0.0'!$B:$B,C10,'Server 2016 v4.0.0'!$G:$G,"Manual step") -> 0 | H10: =COUNTIFS('Server 2016 v4.0.0'!$B:$B,C10,'Server 2016 v4.0.0'!$G:$G,"Different value")+COUNTIFS('Server 2016 v4.0.0'!$B:$B,C10,'Server 2016 v4.0.0'!$G:$G,"Missing") -> 0 | I10: =IFERROR((E10+F10)/D10,0) -> 1
A12: How to read this
A13: • Covered = the script sets exactly what the CIS PDF expects (thresholds such as "or more" / "or fewer" respected).
A14: • Check value = CIS allows a range or an organisation-specific value (logon banner, firewall log path, registry path lists). Confirm the script value fits you.
A15: • Some covered items only apply when you switch them on: LAPS ($ConfigureWindowsLAPS / legacy LAPS client), SMB 3.1.1 minimum and SMB client encryption (off by default), WPAD (on by default). See "Settings added".
A16: • "Compatibility Assurance" switches in the scripts (RDP, Veeam, clipboard, MAPS...) deliberately oppose CIS when set to $true.
A17: • This is a check of what the scripts write, compared with the PDFs. Domain GPOs can override settings - Qualys remains the final check.
A19: Sources
A20: • CIS PDFs supplied by you: Server 2022 v5.1.0, Server 2019 v5.0.0, Server 2016 v4.0.0 (titles, profiles, registry locations and values extracted automatically).
A21: • Base script: community CIS Windows Server 2022 v3.0.0 hardening script, with the fixes and additions listed on "Settings added".

Sheet Server 2022 v5.1.0
A1: CIS ID | B1: Level | C1: CIS recommendation (member server) | D1: CIS type | E1: Registry (from CIS audit) | F1: CIS expected | G1: Status | H1: What the script sets | I1: Script function | J1: Note
A2: 1.1.1 | B2: L1 | C2: Ensure 'Enforce password history' is set to '24 or more password(s)' | D2: Automated | G2: Covered | H2: 1.1.1 (L1) Ensure 'Enforce password history' is set to '24 or more password(s)' (Scored) | I2: EnforcePasswordHistory
A3: 1.1.2 | B3: L1 | C3: Ensure 'Maximum password age' is set to '365 or fewer days, but not 0' | D3: Automated | G3: Covered | H3: 1.1.2 (L1) Ensure 'Maximum password age' is set to '365 or fewer days, but not 0' | I3: MaximumPasswordAge
A4: 1.1.3 | B4: L1 | C4: Ensure 'Minimum password age' is set to '1 or more day(s)' | D4: Automated | G4: Covered | H4: 1.1.3 (L1) Ensure 'Minimum password age' is set to '1 or more day(s)' (Scored) | I4: MinimumPasswordAge
A5: 1.1.4 | B5: L1 | C5: Ensure 'Minimum password length' is set to '14 or more character(s)' | D5: Automated | G5: Covered | H5: 1.1.4 (L1) Ensure 'Minimum password length' is set to '14 or more character(s)' (Scored) | I5: MinimumPasswordLength
A6: 1.1.5 | B6: L1 | C6: Ensure 'Password must meet complexity requirements' is set to 'Enabled' | D6: Automated | G6: Covered | H6: 1.1.5 (L1) Ensure 'Password must meet complexity requirements' is set to 'Enabled' (Scored) | I6: WindowsPasswordComplexityPolicyMustBeEnabled
A7: 1.1.6 | B7: L1 | C7: Ensure 'Relax minimum password length limits' is set to 'Enabled' | D7: Automated | E7: HKLM\System\CurrentControlSet\Control\SAM:RelaxMinimumPasswordLengthLimits | F7: REG_DWORD 1 | G7: Covered | H7: 1 | I7: RelaxMinPasswordLength
A8: 1.1.7 | B8: L1 | C8: Ensure 'Store passwords using reversible encryption' is set to 'Disabled' | D8: Automated | G8: Covered | H8: 1.1.7 (L1) Ensure 'Store passwords using reversible encryption' is set to 'Disabled' (Scored) | I8: DisablePasswordReversibleEncryption
A9: 1.2.1 | B9: L1 | C9: Ensure 'Account lockout duration' is set to '15 or more minute(s)' | D9: Automated | G9: Covered | H9: 1.2.1 (L1) Ensure 'Account lockout duration' is set to '15 or more minute(s)' (Scored) | I9: AccountLockoutDuration
A10: 1.2.2 | B10: L1 | C10: Ensure 'Account lockout threshold' is set to '5 or fewer invalid logon attempt(s), but not 0' | D10: Automated | G10: Covered | H10: 1.2.2 (L1) Ensure 'Account lockout threshold' is set to '5 or fewer invalid logon attempt(s), but not 0' (Scored) | I10: AccountLockoutThreshold
A11: 1.2.3 | B11: L1 | C11: Ensure 'Allow Administrator account lockout' is set to 'Enabled' (MS only) | D11: Manual | G11: Covered | H11: 1.2.3 (L1) Ensure 'Allow Administrator account lockout' is set to 'Enabled' (MS only) | I11: AllowBuiltInAdminAccountLockout
A12: 1.2.4 | B12: L1 | C12: Ensure 'Reset account lockout counter after' is set to '15 or more minute(s)' | D12: Automated | G12: Covered | H12: 1.2.4 (L1) Ensure 'Reset account lockout counter after' is set to '15 or more minute(s)' (Scored) | I12: ResetAccountLockoutCounter
A13: 2.2.1 | B13: L1 | C13: Ensure 'Access Credential Manager as a trusted caller' is set to 'No One' | D13: Automated | G13: Covered | H13: 2.2.1 (L1) Ensure 'Access Credential Manager as a trusted caller' is set to 'No One' (Scored) | I13: NoOneTrustCallerACM
A14: 2.2.3 | B14: L1 | C14: Ensure 'Access this computer from the network' is set to 'Administrators, Authenticated Users' (MS only) | D14: Automated | G14: Covered | H14: 2.2.3 (L1) Ensure 'Access this computer from the network' is set to 'Administrators, Authenticated Users | I14: AccessComputerFromNetwork
A15: 2.2.4 | B15: L1 | C15: Ensure 'Act as part of the operating system' is set to 'No One' | D15: Automated | G15: Covered | H15: 2.2.4 (L1) Ensure 'Act as part of the operating system' is set to 'No One' (Scored) | I15: NoOneActAsPartOfOperatingSystem
A16: 2.2.6 | B16: L1 | C16: Ensure 'Adjust memory quotas for a process' is set to 'Administrators, LOCAL SERVICE, NETWORK SERVICE' | D16: Automated | G16: Covered | H16: 2.2.6 (L1) Ensure 'Adjust memory quotas for a process' is set to 'Administrators, LOCAL SERVICE, NETWORK SERVICE' | I16: AdjustMemoryQuotasForProcess
A17: 2.2.8 | B17: L1 | C17: Ensure 'Allow log on locally' is set to 'Administrators' (MS only) | D17: Automated | G17: Covered | H17: 2.2.8 (L1) Ensure 'Allow log on locally' is set to 'Administrators' | I17: AllowLogonLocallyToAdministrators
A18: 2.2.10 | B18: L1 | C18: Ensure 'Allow log on through Remote Desktop Services' is set to 'Administrators, Remote Desktop Users' (MS only) | D18: Automated | G18: Covered | H18: 2.2.10 (L1) Ensure 'Allow log on through Remote Desktop Services' is set to 'Administrators, Remote Desktop Users' | I18: LogonThroughRemoteDesktopServices
A19: 2.2.11 | B19: L1 | C19: Ensure 'Back up files and directories' is set to 'Administrators' | D19: Automated | G19: Covered | H19: 2.2.11 (L1) Ensure 'Back up files and directories' is set to 'Administrators' | I19: BackupFilesAndDirectories
... A34: 2.2.30 | B34: L1 | C34: Ensure 'Generate security audits' is set to 'LOCAL SERVICE, NETWORK SERVICE' | D34: Automated | G34: Covered | H34: 2.2.31 (L1) Ensure 'Generate security audits' is set to 'LOCAL SERVICE, NETWORK SERVICE' (Scored) | I34: GenerateSecurityAudits
A35: 2.2.32 | B35: L1 | C35: Ensure 'Impersonate a client after authentication' is set to 'Administrators, LOCAL SERVICE, NETWORK SERVICE, SERVICE' (MS only) | D35: Automated | G35: Covered (reviewed) | H35: 2.2.33 (L1) Ensure 'Impersonate a client after authentication' is set to 'Administrators, LOCAL SERVICE, NETWORK SERVICE, SERVICE, IIS_IUSRS' | I35: ImpersonateClientAfterAuthentication | J35: Script title mentions IIS_IUSRS but it sets exactly Administrators, LOCAL SERVICE, NETWORK SERVICE, SERVICE.
A36: 2.2.33 | B36: L1 | C36: Ensure 'Increase scheduling priority' is set to 'Administrators, Window Manager\Window Manager Group' | D36: Automated | G36: Covered | H36: 2.2.34 (L1) Ensure 'Increase scheduling priority' is set to 'Administrators, Window Manager\Window Manager Group' | I36: IncreaseSchedulingPriority
A37: 2.2.34 | B37: L1 | C37: Ensure 'Load and unload device drivers' is set to 'Administrators' | D37: Automated | G37: Covered | H37: 2.2.35 (L1) Ensure 'Load and unload device drivers' is set to 'Administrators' | I37: LoadUnloadDeviceDrivers
A38: 2.2.35 | B38: L1 | C38: Ensure 'Lock pages in memory' is set to 'No One' | D38: Automated | G38: Covered | H38: 2.2.36 (L1) Ensure 'Lock pages in memory' is set to 'No One' | I38: NoOneLockPagesInMemory
A39: 2.2.38 | B39: L1 | C39: Ensure 'Manage auditing and security log' is set to 'Administrators' (MS only) | D39: Automated | G39: Covered | H39: 2.2.39 (L1) Ensure 'Manage auditing and security log' is set to 'Administrators' | I39: ManageAuditingAndSecurity
A40: 2.2.39 | B40: L1 | C40: Ensure 'Modify an object label' is set to 'No One' | D40: Automated | G40: Covered | H40: 2.2.40 (L1) Ensure 'Modify an object label' is set to 'No One' | I40: NoOneModifiesObjectLabel
A41: 2.2.40 | B41: L1 | C41: Ensure 'Modify firmware environment values' is set to 'Administrators' | D41: Automated | G41: Covered | H41: 2.2.41 (L1) Ensure 'Modify firmware environment values' is set to 'Administrators' | I41: FirmwareEnvValues
A42: 2.2.41 | B42: L1 | C42: Ensure 'Perform volume maintenance tasks' is set to 'Administrators' | D42: Automated | G42: Covered | H42: 2.2.42 (L1) Ensure 'Perform volume maintenance tasks' is set to 'Administrators' | I42: VolumeMaintenance
A43: 2.2.42 | B43: L1 | C43: Ensure 'Profile single process' is set to 'Administrators' | D43: Automated | G43: Covered | H43: 2.2.43 (L1) Ensure 'Profile single process' is set to 'Administrators' | I43: ProfileSingleProcess
A44: 2.2.43 | B44: L1 | C44: Ensure 'Profile system performance' is set to 'Administrators, NT SERVICE\WdiServiceHost' | D44: Automated | G44: Covered | H44: 2.2.44 (L1) Ensure 'Profile system performance' is set to 'Administrators,NT SERVICE\WdiServiceHost' | I44: ProfileSystemPerformance
A45: 2.2.44 | B45: L1 | C45: Ensure 'Replace a process level token' is set to 'LOCAL SERVICE, NETWORK SERVICE' | D45: Automated | G45: Covered | H45: 2.2.45 (L1) Ensure 'Replace a process level token' is set to 'LOCAL SERVICE, NETWORK SERVICE' | I45: ReplaceProcessLevelToken
A46: 2.2.45 | B46: L1 | C46: Ensure 'Restore files and directories' is set to 'Administrators' | D46: Automated | G46: Covered | H46: 2.2.46 (L1) Ensure 'Restore files and directories' is set to 'Administrators' | I46: RestoreFilesDirectories
A47: 2.2.46 | B47: L1 | C47: Ensure 'Shut down the system' is set to 'Administrators' | D47: Automated | G47: Covered | H47: 2.2.47 (L1) Ensure 'Shut down the system' is set to 'Administrators' | I47: SystemShutDown
... A49: 2.3.1.1 | B49: L1 | C49: Ensure 'Accounts: Guest account status' is set to 'Disabled' (MS only) | D49: Automated | G49: Covered | H49: 2.3.1.2 (L1) Ensure 'Accounts: Guest account status' is set to 'Disabled' | I49: DisableGuestAccount
A50: 2.3.1.2 | B50: L1 | C50: Ensure 'Accounts: Limit local account use of blank passwords to console logon only' is set to 'Enabled' | D50: Automated | E50: HKLM\SYSTEM\CurrentControlSet\Control\Lsa:LimitBlankPasswordUse | F50: REG_DWORD 1 | G50: Covered | H50: 1 | I50: LimitBlankPasswordConsole
A51: 2.3.1.3 | B51: L1 | C51: Configure 'Accounts: Rename administrator account' | D51: Automated | G51: Covered | H51: 2.3.1.4 (L1) Configure 'Accounts: Rename administrator account' | I51: RenameAdministratorAccount
A52: 2.3.1.4 | B52: L1 | C52: Configure 'Accounts: Rename guest account' | D52: Automated | G52: Covered | H52: 2.3.1.5 (L1) Configure 'Accounts: Rename guest account' | I52: RenameGuestAccount
A53: 2.3.2.1 | B53: L1 | C53: Ensure 'Audit: Force audit policy subcategory settings (Windows Vista or later) to override audit policy category settings' is set to 'Enabled' | D53: Automated | E53: HKLM\SYSTEM\CurrentControlSet\Control\Lsa:SCENoApplyLegacyAuditPolicy | F53: REG_DWORD 1 | G53: Covered | H53: 1 | I53: AuditForceSubCategoryPolicy
A54: 2.3.2.2 | B54: L1 | C54: Ensure 'Audit: Shut down system immediately if unable to log security audits' is set to 'Disabled' | D54: Automated | E54: HKLM\SYSTEM\CurrentControlSet\Control\Lsa:CrashOnAuditFail | F54: REG_DWORD 0 | G54: Covered | H54: 0 | I54: AuditForceShutdown
A55: 2.3.4.1 | B55: L1 | C55: Ensure 'Devices: Prevent users from installing printer drivers' is set to 'Enabled' | D55: Automated | E55: HKLM\SYSTEM\CurrentControlSet\Control\Print\Providers\LanMan Print Services\Servers:AddPrinterDrivers | F55: REG_DWORD 1 | G55: Covered | H55: 1 | I55: PreventPrinterInstallation
...

Sheet Server 2019 v5.0.0
A1: CIS ID | B1: Level | C1: CIS recommendation (member server) | D1: CIS type | E1: Registry (from CIS audit) | F1: CIS expected | G1: Status | H1: What the script sets | I1: Script function | J1: Note
A2: 1.1.1 | B2: L1 | C2: Ensure 'Enforce password history' is set to '24 or more password(s)' | D2: Automated | G2: Covered | H2: 1.1.1 (L1) Ensure 'Enforce password history' is set to '24 or more password(s)' (Scored) | I2: EnforcePasswordHistory
A3: 1.1.2 | B3: L1 | C3: Ensure 'Maximum password age' is set to '365 or fewer days, but not 0' | D3: Automated | G3: Covered | H3: 1.1.2 (L1) Ensure 'Maximum password age' is set to '365 or fewer days, but not 0' | I3: MaximumPasswordAge
A4: 1.1.3 | B4: L1 | C4: Ensure 'Minimum password age' is set to '1 or more day(s)' | D4: Automated | G4: Covered | H4: 1.1.3 (L1) Ensure 'Minimum password age' is set to '1 or more day(s)' (Scored) | I4: MinimumPasswordAge
A5: 1.1.4 | B5: L1 | C5: Ensure 'Minimum password length' is set to '14 or more character(s)' | D5: Automated | G5: Covered | H5: 1.1.4 (L1) Ensure 'Minimum password length' is set to '14 or more character(s)' (Scored) | I5: MinimumPasswordLength
A6: 1.1.5 | B6: L1 | C6: Ensure 'Password must meet complexity requirements' is set to 'Enabled' | D6: Automated | G6: Covered | H6: 1.1.5 (L1) Ensure 'Password must meet complexity requirements' is set to 'Enabled' (Scored) | I6: WindowsPasswordComplexityPolicyMustBeEnabled
A7: 1.1.6 | B7: L1 | C7: Ensure 'Store passwords using reversible encryption' is set to 'Disabled' | D7: Automated | G7: Covered | H7: 1.1.7 (L1) Ensure 'Store passwords using reversible encryption' is set to 'Disabled' (Scored) | I7: DisablePasswordReversibleEncryption
A8: 1.2.1 | B8: L1 | C8: Ensure 'Account lockout duration' is set to '15 or more minute(s)' | D8: Automated | G8: Covered | H8: 1.2.1 (L1) Ensure 'Account lockout duration' is set to '15 or more minute(s)' (Scored) | I8: AccountLockoutDuration
A9: 1.2.2 | B9: L1 | C9: Ensure 'Account lockout threshold' is set to '5 or fewer invalid logon attempt(s), but not 0' | D9: Automated | G9: Covered | H9: 1.2.2 (L1) Ensure 'Account lockout threshold' is set to '5 or fewer invalid logon attempt(s), but not 0' (Scored) | I9: AccountLockoutThreshold
A10: 1.2.3 | B10: L1 | C10: Ensure 'Allow Administrator account lockout' is set to 'Enabled' (MS only) | D10: Manual | G10: Covered | H10: 1.2.3 (L1) Ensure 'Allow Administrator account lockout' is set to 'Enabled' (MS only) | I10: AllowBuiltInAdminAccountLockout
A11: 1.2.4 | B11: L1 | C11: Ensure 'Reset account lockout counter after' is set to '15 or more minute(s)' | D11: Automated | G11: Covered | H11: 1.2.4 (L1) Ensure 'Reset account lockout counter after' is set to '15 or more minute(s)' (Scored) | I11: ResetAccountLockoutCounter
A12: 2.2.1 | B12: L1 | C12: Ensure 'Access Credential Manager as a trusted caller' is set to 'No One' | D12: Automated | G12: Covered | H12: 2.2.1 (L1) Ensure 'Access Credential Manager as a trusted caller' is set to 'No One' (Scored) | I12: NoOneTrustCallerACM
A13: 2.2.3 | B13: L1 | C13: Ensure 'Access this computer from the network' is set to 'Administrators, Authenticated Users' (MS only) | D13: Automated | G13: Covered | H13: 2.2.3 (L1) Ensure 'Access this computer from the network' is set to 'Administrators, Authenticated Users | I13: AccessComputerFromNetwork
... A33: 2.2.30 | B33: L1 | C33: Ensure 'Generate security audits' is set to 'LOCAL SERVICE, NETWORK SERVICE' | D33: Automated | G33: Covered | H33: 2.2.31 (L1) Ensure 'Generate security audits' is set to 'LOCAL SERVICE, NETWORK SERVICE' (Scored) | I33: GenerateSecurityAudits
A34: 2.2.32 | B34: L1 | C34: Ensure 'Impersonate a client after authentication' is set to 'Administrators, LOCAL SERVICE, NETWORK SERVICE, SERVICE' (MS only) | D34: Automated | G34: Covered (reviewed) | H34: 2.2.33 (L1) Ensure 'Impersonate a client after authentication' is set to 'Administrators, LOCAL SERVICE, NETWORK SERVICE, SERVICE, IIS_IUSRS' | I34: ImpersonateClientAfterAuthentication | J34: Script title mentions IIS_IUSRS but it sets exactly Administrators, LOCAL SERVICE, NETWORK SERVICE, SERVICE.
A35: 2.2.33 | B35: L1 | C35: Ensure 'Impersonate a client after authentication' is set to 'Administrators, LOCAL SERVICE, NETWORK SERVICE, SERVICE, RESTRICTED SERVICES\PrintSpoolerService' (MS only) | D35: Automated | G35: Covered (reviewed) | H35: 2.2.33 (L1) Ensure 'Impersonate a client after authentication' is set to 'Administrators, LOCAL SERVICE, NETWORK SERVICE, SERVICE, IIS_IUSRS' | I35: ImpersonateClientAfterAuthentication | J35: Script title mentions IIS_IUSRS but it sets exactly Administrators, LOCAL SERVICE, NETWORK SERVICE, SERVICE.
A36: 2.2.34 | B36: L1 | C36: Ensure 'Increase scheduling priority' is set to 'Administrators, Window Manager\Window Manager Group' | D36: Automated | G36: Covered | H36: 2.2.34 (L1) Ensure 'Increase scheduling priority' is set to 'Administrators, Window Manager\Window Manager Group' | I36: IncreaseSchedulingPriority
A37: 2.2.35 | B37: L1 | C37: Ensure 'Load and unload device drivers' is set to 'Administrators' | D37: Automated | G37: Covered | H37: 2.2.35 (L1) Ensure 'Load and unload device drivers' is set to 'Administrators' | I37: LoadUnloadDeviceDrivers
A38: 2.2.36 | B38: L1 | C38: Ensure 'Lock pages in memory' is set to 'No One' | D38: Automated | G38: Covered | H38: 2.2.36 (L1) Ensure 'Lock pages in memory' is set to 'No One' | I38: NoOneLockPagesInMemory
A39: 2.2.39 | B39: L1 | C39: Ensure 'Manage auditing and security log' is set to 'Administrators' (MS only) | D39: Automated | G39: Covered | H39: 2.2.39 (L1) Ensure 'Manage auditing and security log' is set to 'Administrators' | I39: ManageAuditingAndSecurity
A40: 2.2.40 | B40: L1 | C40: Ensure 'Modify an object label' is set to 'No One' | D40: Automated | G40: Covered | H40: 2.2.40 (L1) Ensure 'Modify an object label' is set to 'No One' | I40: NoOneModifiesObjectLabel
A41: 2.2.41 | B41: L1 | C41: Ensure 'Modify firmware environment values' is set to 'Administrators' | D41: Automated | G41: Covered | H41: 2.2.41 (L1) Ensure 'Modify firmware environment values' is set to 'Administrators' | I41: FirmwareEnvValues
A42: 2.2.42 | B42: L1 | C42: Ensure 'Perform volume maintenance tasks' is set to 'Administrators' | D42: Automated | G42: Covered | H42: 2.2.42 (L1) Ensure 'Perform volume maintenance tasks' is set to 'Administrators' | I42: VolumeMaintenance
A43: 2.2.43 | B43: L1 | C43: Ensure 'Profile single process' is set to 'Administrators' | D43: Automated | G43: Covered | H43: 2.2.43 (L1) Ensure 'Profile single process' is set to 'Administrators' | I43: ProfileSingleProcess
A44: 2.2.44 | B44: L1 | C44: Ensure 'Profile system performance' is set to 'Administrators, NT SERVICE\WdiServiceHost' | D44: Automated | G44: Covered | H44: 2.2.44 (L1) Ensure 'Profile system performance' is set to 'Administrators,NT SERVICE\WdiServiceHost' | I44: ProfileSystemPerformance
A45: 2.2.45 | B45: L1 | C45: Ensure 'Replace a process level token' is set to 'LOCAL SERVICE, NETWORK SERVICE' | D45: Automated | G45: Covered | H45: 2.2.45 (L1) Ensure 'Replace a process level token' is set to 'LOCAL SERVICE, NETWORK SERVICE' | I45: ReplaceProcessLevelToken
A46: 2.2.46 | B46: L1 | C46: Ensure 'Restore files and directories' is set to 'Administrators' | D46: Automated | G46: Covered | H46: 2.2.46 (L1) Ensure 'Restore files and directories' is set to 'Administrators' | I46: RestoreFilesDirectories
A47: 2.2.47 | B47: L1 | C47: Ensure 'Shut down the system' is set to 'Administrators' | D47: Automated | G47: Covered | H47: 2.2.47 (L1) Ensure 'Shut down the system' is set to 'Administrators' | I47: SystemShutDown
... A49: 2.3.1.1 | B49: L1 | C49: Ensure 'Accounts: Guest account status' is set to 'Disabled' (MS only) | D49: Automated | G49: Covered | H49: 2.3.1.2 (L1) Ensure 'Accounts: Guest account status' is set to 'Disabled' | I49: DisableGuestAccount
A50: 2.3.1.2 | B50: L1 | C50: Ensure 'Accounts: Limit local account use of blank passwords to console logon only' is set to 'Enabled' | D50: Automated | E50: HKLM\SYSTEM\CurrentControlSet\Control\Lsa:LimitBlankPasswordUse | F50: REG_DWORD 1 | G50: Covered | H50: 1 | I50: LimitBlankPasswordConsole
A51: 2.3.1.3 | B51: L1 | C51: Configure 'Accounts: Rename administrator account' | D51: Automated | G51: Covered | H51: 2.3.1.4 (L1) Configure 'Accounts: Rename administrator account' | I51: RenameAdministratorAccount
A52: 2.3.1.4 | B52: L1 | C52: Configure 'Accounts: Rename guest account' | D52: Automated | G52: Covered | H52: 2.3.1.5 (L1) Configure 'Accounts: Rename guest account' | I52: RenameGuestAccount
A53: 2.3.2.1 | B53: L1 | C53: Ensure 'Audit: Force audit policy subcategory settings (Windows Vista or later) to override audit policy category settings' is set to 'Enabled' | D53: Automated | E53: HKLM\SYSTEM\CurrentControlSet\Control\Lsa:SCENoApplyLegacyAuditPolicy | F53: REG_DWORD 1 | G53: Covered | H53: 1 | I53: AuditForceSubCategoryPolicy
A54: 2.3.2.2 | B54: L1 | C54: Ensure 'Audit: Shut down system immediately if unable to log security audits' is set to 'Disabled' | D54: Automated | E54: HKLM\SYSTEM\CurrentControlSet\Control\Lsa:CrashOnAuditFail | F54: REG_DWORD 0 | G54: Covered | H54: 0 | I54: AuditForceShutdown
A55: 2.3.4.1 | B55: L1 | C55: Ensure 'Devices: Prevent users from installing printer drivers' is set to 'Enabled' | D55: Automated | E55: HKLM\SYSTEM\CurrentControlSet\Control\Print\Providers\LanMan Print Services\Servers:AddPrinterDrivers | F55: REG_DWORD 1 | G55: Covered | H55: 1 | I55: PreventPrinterInstallation
A56: 2.3.6.1 | B56: L1 | C56: Ensure 'Domain member: Digitally encrypt or sign secure channel data (always)' is set to 'Enabled' | D56: Automated | E56: HKLM\SYSTEM\CurrentControlSet\Services\Netlogon\Parameters:RequireSignOrSeal | F56: REG_DWORD 1 | G56: Covered | H56: 1 | I56: SignEncryptAllChannelData
A57: 2.3.6.2 | B57: L1 | C57: Ensure 'Domain member: Digitally encrypt secure channel data (when possible)' is set to 'Enabled' | D57: Automated | E57: HKLM\SYSTEM\CurrentControlSet\Services\Netlogon\Parameters:SealSecureChannel | F57: REG_DWORD 1 | G57: Covered | H57: 1 | I57: SecureChannelWhenPossible
A58: 2.3.6.3 | B58: L1 | C58: Ensure 'Domain member: Digitally sign secure channel data (when possible)' is set to 'Enabled' | D58: Automated | E58: HKLM\SYSTEM\CurrentControlSet\Services\Netlogon\Parameters:SignSecureChannel | F58: REG_DWORD 1 | G58: Covered | H58: 1 | I58: DigitallySignChannelWhenPossible
A59: 2.3.6.4 | B59: L1 | C59: Ensure 'Domain member: Disable machine account password changes' is set to 'Disabled' | D59: Automated | E59: HKLM\SYSTEM\CurrentControlSet\Services\Netlogon\Parameters:DisablePasswordChange | F59: REG_DWORD 0 | G59: Covered | H59: 0 | I59: EnableAccountPasswordChanges
A60: 2.3.6.5 | B60: L1 | C60: Ensure 'Domain member: Maximum machine account password age' is set to '30 or fewer days, but not 0' | D60: Automated | E60: HKLM\System\CurrentControlSet\Services\Netlogon\Parameters:MaximumPasswordAge | F60: REG_DWORD 30 or less, but not 0 | G60: Covered | H60: 30 | I60: MaximumAccountPasswordAge
...

Sheet Server 2016 v4.0.0
A1: CIS ID | B1: Level | C1: CIS recommendation (member server) | D1: CIS type | E1: Registry (from CIS audit) | F1: CIS expected | G1: Status | H1: What the script sets | I1: Script function | J1: Note
A2: 1.1.1 | B2: L1 | C2: (L1) Ensure 'Enforce password history' is set to '24 or more password(s)' | D2: Automated | G2: Covered | H2: 1.1.1 (L1) Ensure 'Enforce password history' is set to '24 or more password(s)' (Scored) | I2: EnforcePasswordHistory
A3: 1.1.2 | B3: L1 | C3: (L1) Ensure 'Maximum password age' is set to '365 or fewer days, but not 0' | D3: Automated | G3: Covered | H3: 1.1.2 (L1) Ensure 'Maximum password age' is set to '365 or fewer days, but not 0' | I3: MaximumPasswordAge
A4: 1.1.3 | B4: L1 | C4: (L1) Ensure 'Minimum password age' is set to '1 or more day(s)' | D4: Automated | G4: Covered | H4: 1.1.3 (L1) Ensure 'Minimum password age' is set to '1 or more day(s)' (Scored) | I4: MinimumPasswordAge
A5: 1.1.4 | B5: L1 | C5: (L1) Ensure 'Minimum password length' is set to '14 or more character(s)' | D5: Automated | G5: Covered | H5: 1.1.4 (L1) Ensure 'Minimum password length' is set to '14 or more character(s)' (Scored) | I5: MinimumPasswordLength
A6: 1.1.5 | B6: L1 | C6: (L1) Ensure 'Password must meet complexity requirements' is set to 'Enabled' | D6: Automated | G6: Covered | H6: 1.1.5 (L1) Ensure 'Password must meet complexity requirements' is set to 'Enabled' (Scored) | I6: WindowsPasswordComplexityPolicyMustBeEnabled
A7: 1.1.6 | B7: L1 | C7: (L1) Ensure 'Store passwords using reversible encryption' is set to 'Disabled' | D7: Automated | G7: Covered | H7: 1.1.7 (L1) Ensure 'Store passwords using reversible encryption' is set to 'Disabled' (Scored) | I7: DisablePasswordReversibleEncryption
A8: 1.2.1 | B8: L1 | C8: (L1) Ensure 'Account lockout duration' is set to '15 or more minute(s)' | D8: Automated | G8: Covered | H8: 1.2.1 (L1) Ensure 'Account lockout duration' is set to '15 or more minute(s)' (Scored) | I8: AccountLockoutDuration
A9: 1.2.2 | B9: L1 | C9: (L1) Ensure 'Account lockout threshold' is set to '5 or fewer invalid logon attempt(s), but not 0' | D9: Automated | G9: Covered | H9: 1.2.2 (L1) Ensure 'Account lockout threshold' is set to '5 or fewer invalid logon attempt(s), but not 0' (Scored) | I9: AccountLockoutThreshold
A10: 1.2.3 | B10: L1 | C10: (L1) Ensure 'Allow Administrator account lockout' is set to 'Enabled' (MS only) | D10: Manual | G10: Covered | H10: 1.2.3 (L1) Ensure 'Allow Administrator account lockout' is set to 'Enabled' (MS only) | I10: AllowBuiltInAdminAccountLockout
A11: 1.2.4 | B11: L1 | C11: (L1) Ensure 'Reset account lockout counter after' is set to '15 or more minute(s)' | D11: Automated | G11: Covered | H11: 1.2.4 (L1) Ensure 'Reset account lockout counter after' is set to '15 or more minute(s)' (Scored) | I11: ResetAccountLockoutCounter
A12: 2.2.1 | B12: L1 | C12: (L1) Ensure 'Access Credential Manager as a trusted caller' is set to 'No One' | D12: Automated | G12: Covered | H12: 2.2.1 (L1) Ensure 'Access Credential Manager as a trusted caller' is set to 'No One' (Scored) | I12: NoOneTrustCallerACM
A13: 2.2.3 | B13: L1 | C13: (L1) Ensure 'Access this computer from the network' is set to 'Administrators, Authenticated Users' (MS only) | D13: Automated | G13: Covered | H13: 2.2.3 (L1) Ensure 'Access this computer from the network' is set to 'Administrators, Authenticated Users | I13: AccessComputerFromNetwork
... A34: 2.2.31 | B34: L1 | C34: (L1) Ensure 'Generate security audits' is set to 'LOCAL SERVICE, NETWORK SERVICE' | D34: Automated | G34: Covered | H34: 2.2.31 (L1) Ensure 'Generate security audits' is set to 'LOCAL SERVICE, NETWORK SERVICE' (Scored) | I34: GenerateSecurityAudits
A35: 2.2.33 | B35: L1 | C35: (L1) Ensure 'Impersonate a client after authentication' is set to 'Administrators, LOCAL SERVICE, NETWORK SERVICE, SERVICE' and (when the Web Server (IIS) Role with Web Services Role Service is installed) 'IIS_IUSRS' (MS only) | D35: Automated | G35: Covered (reviewed) | H35: 2.2.33 (L1) Ensure 'Impersonate a client after authentication' is set to 'Administrators, LOCAL SERVICE, NETWORK SERVICE, SERVICE, IIS_IUSRS' | I35: ImpersonateClientAfterAuthentication | J35: Script title mentions IIS_IUSRS but it sets exactly Administrators, LOCAL SERVICE, NETWORK SERVICE, SERVICE.
A36: 2.2.34 | B36: L1 | C36: (L1) Ensure 'Increase scheduling priority' is set to 'Administrators' | D36: Automated | G36: Covered | H36: 2.2.34 (L1) Ensure 'Increase scheduling priority' is set to 'Administrators' | I36: IncreaseSchedulingPriority
A37: 2.2.35 | B37: L1 | C37: (L1) Ensure 'Load and unload device drivers' is set to 'Administrators' | D37: Automated | G37: Covered | H37: 2.2.35 (L1) Ensure 'Load and unload device drivers' is set to 'Administrators' | I37: LoadUnloadDeviceDrivers
A38: 2.2.36 | B38: L1 | C38: (L1) Ensure 'Lock pages in memory' is set to 'No One' | D38: Automated | G38: Covered | H38: 2.2.36 (L1) Ensure 'Lock pages in memory' is set to 'No One' | I38: NoOneLockPagesInMemory
A39: 2.2.39 | B39: L1 | C39: (L1) Ensure 'Manage auditing and security log' is set to 'Administrators' (MS only) | D39: Automated | G39: Covered | H39: 2.2.39 (L1) Ensure 'Manage auditing and security log' is set to 'Administrators' | I39: ManageAuditingAndSecurity
A40: 2.2.40 | B40: L1 | C40: (L1) Ensure 'Modify an object label' is set to 'No One' | D40: Automated | G40: Covered | H40: 2.2.40 (L1) Ensure 'Modify an object label' is set to 'No One' | I40: NoOneModifiesObjectLabel
A41: 2.2.41 | B41: L1 | C41: (L1) Ensure 'Modify firmware environment values' is set to 'Administrators' | D41: Automated | G41: Covered | H41: 2.2.41 (L1) Ensure 'Modify firmware environment values' is set to 'Administrators' | I41: FirmwareEnvValues
A42: 2.2.42 | B42: L1 | C42: (L1) Ensure 'Perform volume maintenance tasks' is set to 'Administrators' | D42: Automated | G42: Covered | H42: 2.2.42 (L1) Ensure 'Perform volume maintenance tasks' is set to 'Administrators' | I42: VolumeMaintenance
A43: 2.2.43 | B43: L1 | C43: (L1) Ensure 'Profile single process' is set to 'Administrators' | D43: Automated | G43: Covered | H43: 2.2.43 (L1) Ensure 'Profile single process' is set to 'Administrators' | I43: ProfileSingleProcess
A44: 2.2.44 | B44: L1 | C44: (L1) Ensure 'Profile system performance' is set to 'Administrators, NT SERVICE\WdiServiceHost' | D44: Automated | G44: Covered | H44: 2.2.44 (L1) Ensure 'Profile system performance' is set to 'Administrators,NT SERVICE\WdiServiceHost' | I44: ProfileSystemPerformance
A45: 2.2.45 | B45: L1 | C45: (L1) Ensure 'Replace a process level token' is set to 'LOCAL SERVICE, NETWORK SERVICE' | D45: Automated | G45: Covered | H45: 2.2.45 (L1) Ensure 'Replace a process level token' is set to 'LOCAL SERVICE, NETWORK SERVICE' | I45: ReplaceProcessLevelToken
A46: 2.2.46 | B46: L1 | C46: (L1) Ensure 'Restore files and directories' is set to 'Administrators' | D46: Automated | G46: Covered | H46: 2.2.46 (L1) Ensure 'Restore files and directories' is set to 'Administrators' | I46: RestoreFilesDirectories
A47: 2.2.47 | B47: L1 | C47: (L1) Ensure 'Shut down the system' is set to 'Administrators' | D47: Automated | G47: Covered | H47: 2.2.47 (L1) Ensure 'Shut down the system' is set to 'Administrators' | I47: SystemShutDown
A48: 2.2.49 | B48: L1 | C48: (L1) Ensure 'Take ownership of files or other objects' is set to 'Administrators' | D48: Automated | G48: Covered | H48: 2.2.49 (L1) Ensure 'Take ownership of files or other objects' is set to 'Administrators' | I48: TakeOwnershipFiles
A49: 2.3.1.1 | B49: L1 | C49: (L1) Ensure 'Accounts: Block Microsoft accounts' is set to 'Users can't add or log on with Microsoft accounts' | D49: Automated | E49: HKLM\SOFTWARE\Microsoft\Windows\CurrentVersion\Policies\System:NoConnectedUser | F49: REG_DWORD 3 | G49: Covered | H49: 3 | I49: DisableMicrosoftAccounts
A50: 2.3.1.2 | B50: L1 | C50: (L1) Ensure 'Accounts: Guest account status' is set to 'Disabled' (MS only) | D50: Automated | G50: Covered | H50: 2.3.1.2 (L1) Ensure 'Accounts: Guest account status' is set to 'Disabled' | I50: DisableGuestAccount
A51: 2.3.1.3 | B51: L1 | C51: (L1) Ensure 'Accounts: Limit local account use of blank passwords to console logon only' is set to 'Enabled' | D51: Automated | E51: HKLM\SYSTEM\CurrentControlSet\Control\Lsa:LimitBlankPasswordUse | F51: REG_DWORD 1 | G51: Covered | H51: 1 | I51: LimitBlankPasswordConsole
A52: 2.3.1.4 | B52: L1 | C52: (L1) Configure 'Accounts: Rename administrator account' | D52: Automated | G52: Covered | H52: 2.3.1.4 (L1) Configure 'Accounts: Rename administrator account' | I52: RenameAdministratorAccount
A53: 2.3.1.5 | B53: L1 | C53: (L1) Configure 'Accounts: Rename guest account' | D53: Automated | G53: Covered | H53: 2.3.1.5 (L1) Configure 'Accounts: Rename guest account' | I53: RenameGuestAccount
A54: 2.3.2.1 | B54: L1 | C54: (L1) Ensure 'Audit: Force audit policy subcategory settings (Windows Vista or later) to override audit policy category settings' is set to 'Enabled' | D54: Automated | E54: HKLM\SYSTEM\CurrentControlSet\Control\Lsa:SCENoApplyLegacyAuditPolicy | F54: REG_DWORD 1 | G54: Covered | H54: 1 | I54: AuditForceSubCategoryPolicy
A55: 2.3.2.2 | B55: L1 | C55: (L1) Ensure 'Audit: Shut down system immediately if unable to log security audits' is set to 'Disabled' | D55: Automated | E55: HKLM\SYSTEM\CurrentControlSet\Control\Lsa:CrashOnAuditFail | F55: REG_DWORD 0 | G55: Covered | H55: 0 | I55: AuditForceShutdown
A56: 2.3.4.1 | B56: L1 | C56: (L1) Ensure 'Devices: Prevent users from installing printer drivers' is set to 'Enabled' | D56: Automated | E56: HKLM\SYSTEM\CurrentControlSet\Control\Print\Providers\LanMan Print Services\Servers:AddPrinterDrivers | F56: REG_DWORD 1 | G56: Covered | H56: 1 | I56: PreventPrinterInstallation
A57: 2.3.6.1 | B57: L1 | C57: (L1) Ensure 'Domain member: Digitally encrypt or sign secure channel data (always)' is set to 'Enabled' | D57: Automated | E57: HKLM\SYSTEM\CurrentControlSet\Services\Netlogon\Parameters:RequireSignOrSeal | F57: REG_DWORD 1 | G57: Covered | H57: 1 | I57: SignEncryptAllChannelData
A58: 2.3.6.2 | B58: L1 | C58: (L1) Ensure 'Domain member: Digitally encrypt secure channel data (when possible)' is set to 'Enabled' | D58: Automated | E58: HKLM\SYSTEM\CurrentControlSet\Services\Netlogon\Parameters:SealSecureChannel | F58: REG_DWORD 1 | G58: Covered | H58: 1 | I58: SecureChannelWhenPossible
A59: 2.3.6.3 | B59: L1 | C59: (L1) Ensure 'Domain member: Digitally sign secure channel data (when possible)' is set to 'Enabled' | D59: Automated | E59: HKLM\SYSTEM\CurrentControlSet\Services\Netlogon\Parameters:SignSecureChannel | F59: REG_DWORD 1 | G59: Covered | H59: 1 | I59: DigitallySignChannelWhenPossible
A60: 2.3.6.4 | B60: L1 | C60: (L1) Ensure 'Domain member: Disable machine account password changes' is set to 'Disabled' | D60: Automated | E60: HKLM\SYSTEM\CurrentControlSet\Services\Netlogon\Parameters:DisablePasswordChange | F60: REG_DWORD 0 | G60: Covered | H60: 0 | I60: EnableAccountPasswordChanges
...

Sheet Settings added
A1: CIS ID | B1: Level | C1: Recommendation | D1: Registry | E1: Value | F1: Servers | G1: Switch (off = not applied) | H1: Risk / note
A2: 18.6.4.1 | B2: L1 | C2: Ensure 'Configure multicast DNS (mDNS) protocol' is set to 'Disabled' | D2: HKLM:\SOFTWARE\Policies\Microsoft\Windows NT\DNSClient\EnableMDNS | E2: 0 | F2: 2022, 2019, 2016 | G2: always applied
A3: 18.6.4.3 | B3: L2 | C3: Ensure 'Turn off default IPv6 DNS Servers' is set to 'Enabled' | D3: HKLM:\SOFTWARE\Policies\Microsoft\Windows NT\DNSClient\DisableIPv6DefaultDnsServers | E3: 1 | F3: 2022, 2019, 2016 | G3: always applied
A4: 18.6.7.1 | B4: L1 | C4: Ensure 'Mandate the minimum version of SMB' is set to 'Enabled: 3.1.1' | D4: HKLM:\SOFTWARE\Policies\Microsoft\Windows\LanmanServer\MinSmb2Dialect | E4: 785 | F4: 2022 | G4: $EnableSMB311Minimum (default $false) | H4: RISK: clients older than Windows 10 / Server 2016 (and many NAS/scanners) can no longer connect to shares on this server.
A5: 18.6.8.2 | B5: L1 | C5: Ensure 'Require Encryption' is set to 'Enabled' | D5: HKLM:\SOFTWARE\Policies\Microsoft\Windows\LanmanWorkstation\RequireEncryption | E5: 1 | F5: 2022 | G5: $RequireSMBClientEncryption (default $false) | H5: RISK: this server can no longer open shares on devices that do not support SMB encryption (older NAS, Linux Samba without encryption, printers).
A6: 18.9.17.1 | B6: L1 | C6: Ensure 'Enable / disable CLFS logfile authentication' is set to 'Enabled' | D6: HKLM:\SYSTEM\CurrentControlSet\Policies\ClfsAuthenticationChecking | E6: 1 | F6: 2022, 2019 | G6: always applied
A7: 18.10.18.4 | B7: L1 | C7: Ensure 'Enable App Installer Local Archive Malware Scan Override' is set to 'Disabled' | D7: HKLM:\SOFTWARE\Policies\Microsoft\Windows\AppInstaller\EnableLocalArchiveMalwareScanOverride | E7: 0 | F7: 2022, 2019 | G7: always applied
A8: 18.10.18.5 | B8: L1 | C8: Ensure 'Enable App Installer Microsoft Store Source Certificate Validation Bypass' is set to 'Disabled' | D8: HKLM:\SOFTWARE\Policies\Microsoft\Windows\AppInstaller\EnableBypassCertificatePinningForMicrosoftStore | E8: 0 | F8: 2022, 2019 | G8: always applied
A9: 18.10.18.7 | B9: L2 | C9: Ensure 'Enable Windows Package Manager command line interfaces' is set to 'Disabled' | D9: HKLM:\SOFTWARE\Policies\Microsoft\Windows\AppInstaller\EnableWindowsPackageManagerCommandLineInterfaces | E9: 0 | F9: 2022, 2019 | G9: always applied | H9: Blocks the winget command line (L2).
A10: 18.10.29.2 | B10: L1 | C10: Ensure 'Do not apply the Mark of the Web tag to files copied from insecure sources' is set to 'Disabled' | D10: HKLM:\SOFTWARE\Policies\Microsoft\Windows\Explorer\DisableMotWOnInsecurePathCopy | E10: 0 | F10: 2022, 2019, 2016 | G10: always applied
A11: 18.10.58.2 | B11: L1 | C11: Ensure 'Turn on Basic feed authentication over HTTP' is set to 'Disabled' | D11: HKLM:\Software\Policies\Microsoft\Internet Explorer\Feeds\AllowBasicAuthInClear | E11: 0 | F11: 2022, 2019, 2016 | G11: always applied
A12: 18.11.1 | B12: L1 | C12: Ensure 'Disable HTTP proxy features: Disable WPAD' is set to 'Enabled: Checked' | D12: HKLM:\SOFTWARE\Microsoft\Windows\CurrentVersion\Internet Settings\WinHttp\DisableWpad | E12: 1 | F12: 2022, 2019 | G12: $DisableWPADProxyDiscovery (default $true) | H12: RISK: servers that find their proxy automatically via WPAD (DHCP/DNS "wpad") lose automatic proxy discovery.
A13: 18.11.2 | B13: L1 | C13: Ensure 'Disable HTTP proxy features: Disable proxy authentication' is set to 'Enabled: Disable authentication over loopback interfaces' or higher | D13: HKLM:\SOFTWARE\Microsoft\Windows\CurrentVersion\Internet Settings\DisableProxyAuthenticationSchemes | E13: 256 | F13: 2022 | G13: always applied
A14: 18.10.43.4.1 | B14: L1 | C14: Ensure 'Enable EDR in block mode' is set to 'Enabled' | D14: HKLM:\SOFTWARE\Policies\Microsoft\Windows Defender\Features\PassiveRemediation | E14: 1 | F14: 2016 | G14: always applied | H14: Takes effect with Microsoft Defender for Endpoint.
A15: 18.10.43.8.1 | B15: L2 | C15: Ensure 'Convert warn verdict to block' is set to 'Enabled' | D15: HKLM:\SOFTWARE\Policies\Microsoft\Windows Defender\NIS\EnableConvertWarnToBlock | E15: 1 | F15: 2016 | G15: always applied
A16: 18.10.43.10.1 | B16: L1 | C16: Ensure 'Configure real-time protection and Security Intelligence Updates during OOBE' is set to 'Enabled' | D16: HKLM:\SOFTWARE\Policies\Microsoft\Windows Defender\Real-Time Protection\OobeEnableRtpAndSigUpdate | E16: 1 | F16: 2016 | G16: always applied
A17: 18.10.43.11.1.1.1 | B17: L2 | C17: Ensure 'Configure Brute-Force Protection aggressiveness' is set to 'Enabled: Medium' or higher | D17: HKLM:\SOFTWARE\Policies\Microsoft\Windows Defender\Remediation\Behavioral Network Blocks\Brute Force Protection\BruteForceProtectionAggressiveness | E17: 1 | F17: 2016 | G17: always applied | H17: 1 = Medium
A18: 18.10.43.11.1.1.2 | B18: L1 | C18: Ensure 'Configure Remote Encryption Protection Mode' is set to 'Enabled: Audit' or higher | D18: HKLM:\SOFTWARE\Policies\Microsoft\Windows Defender\Remediation\Behavioral Network Blocks\Brute Force Protection\BruteForceProtectionConfiguredState | E18: 2 | F18: 2016 | G18: always applied | H18: 2 = Audit (CIS minimum). Use 1 = Block for stronger protection once tested.
A19: 18.10.43.11.1.2.1 | B19: L2 | C19: Ensure 'Configure how aggressively Remote Encryption Protection blocks threats' is set to 'Enabled: Medium' or higher | D19: HKLM:\SOFTWARE\Policies\Microsoft\Windows Defender\Remediation\Behavioral Network Blocks\Remote Encryption Protection\RemoteEncryptionProtectionAggressiveness | E19: 1 | F19: 2016 | G19: always applied | H19: 1 = Medium
A20: 18.10.43.13.1 | B20: L1 | C20: Ensure 'Scan excluded files and directories during quick scans' is set to 'Enabled: 1' | D20: HKLM:\SOFTWARE\Policies\Microsoft\Windows Defender\Scan\QuickScanIncludeExclusions | E20: 1 | F20: 2016 | G20: always applied
A21: 18.10.43.13.4 | B21: L1 | C21: Ensure 'Trigger a quick scan after X days without any scans' is set to 'Enabled: 7' | D21: HKLM:\SOFTWARE\Policies\Microsoft\Windows Defender\Scan\DaysUntilAggressiveCatchupQuickScan | E21: 7 | F21: 2016 | G21: always applied
A22: 18.10.43.17 | B22: L1 | C22: Ensure 'Control whether exclusions are visible to local users' is set to 'Enabled' | D22: HKLM:\SOFTWARE\Policies\Microsoft\Windows Defender\HideExclusionsFromLocalUsers | E22: 1 | F22: 2016 | G22: always applied
A24: Corrections to existing script settings
A25: • 17.8.1 Audit Sensitive Privilege Use: now Success only (2022 v5.1 and 2019 v5.0 changed from Success and Failure).
A26: • 18.6.21.1 Minimize simultaneous connections: 1 on Server 2016 (v4 value); 2019/2022 keep 3.
A27: • 2.2.34 Increase scheduling priority: Administrators only on Server 2016 (v4 value).
A28: • 2.2.33 Impersonate a client: title typo fixed (value was already correct).
A29: • Earlier fixes still included: 17.5.6 Special Logon bug, NetBIOS value 2, 2.2.29 delegation = No One, LAPS (optional).
